2020-02-25 14:30:10,211 ERROR: Exception on /login [GET] [in c:\v_playground\lib\site-packages\flask\app.py:1891]
Traceback (most recent call last):
  File "c:\v_playground\lib\site-packages\flask\app.py", line 2446, in wsgi_app
    response = self.full_dispatch_request()
  File "c:\v_playground\lib\site-packages\flask\app.py", line 1951, in full_dispatch_request
    rv = self.handle_user_exception(e)
  File "c:\v_playground\lib\site-packages\flask\app.py", line 1820, in handle_user_exception
    reraise(exc_type, exc_value, tb)
  File "c:\v_playground\lib\site-packages\flask\_compat.py", line 39, in reraise
    raise value
  File "c:\v_playground\lib\site-packages\flask\app.py", line 1949, in full_dispatch_request
    rv = self.dispatch_request()
  File "c:\v_playground\lib\site-packages\flask\app.py", line 1935, in dispatch_request
    return self.view_functions[rule.endpoint](**req.view_args)
  File "C:\GH\microblog\app\routes.py", line 71, in login
    return render_template('login.html', title='Sign In', form=form)
  File "c:\v_playground\lib\site-packages\flask\templating.py", line 140, in render_template
    ctx.app,
  File "c:\v_playground\lib\site-packages\flask\templating.py", line 120, in _render
    rv = template.render(context)
  File "c:\v_playground\lib\site-packages\jinja2\environment.py", line 1090, in render
    self.environment.handle_exception()
  File "c:\v_playground\lib\site-packages\jinja2\environment.py", line 832, in handle_exception
    reraise(*rewrite_traceback_stack(source=source))
  File "c:\v_playground\lib\site-packages\jinja2\_compat.py", line 28, in reraise
    raise value.with_traceback(tb)
  File "C:\GH\microblog\app\templates\login.html", line 1, in top-level template code
    {% extends "base.html" %}
  File "c:\v_playground\lib\site-packages\jinja2\environment.py", line 832, in handle_exception
    reraise(*rewrite_traceback_stack(source=source))
  File "c:\v_playground\lib\site-packages\jinja2\_compat.py", line 28, in reraise
    raise value.with_traceback(tb)
  File "C:\GH\microblog\app\templates\base.html", line 48, in template
    {% block app_content %}{% endblock %}
jinja2.exceptions.TemplateAssertionError: block 'app_content' defined twice
2020-02-25 14:30:10,489 ERROR: Exception on /favicon.ico [GET] [in c:\v_playground\lib\site-packages\flask\app.py:1891]
Traceback (most recent call last):
  File "c:\v_playground\lib\site-packages\flask\app.py", line 1949, in full_dispatch_request
    rv = self.dispatch_request()
  File "c:\v_playground\lib\site-packages\flask\app.py", line 1925, in dispatch_request
    self.raise_routing_exception(req)
  File "c:\v_playground\lib\site-packages\flask\app.py", line 1907, in raise_routing_exception
    raise request.routing_exception
  File "c:\v_playground\lib\site-packages\flask\ctx.py", line 350, in match_request
    result = self.url_adapter.match(return_rule=True)
  File "c:\v_playground\lib\site-packages\werkzeug\routing.py", line 1945, in match
    raise NotFound()
werkzeug.exceptions.NotFound: 404 Not Found: The requested URL was not found on the server. If you entered the URL manually please check your spelling and try again.

During handling of the above exception, another exception occurred:

Traceback (most recent call last):
  File "c:\v_playground\lib\site-packages\flask\app.py", line 2446, in wsgi_app
    response = self.full_dispatch_request()
  File "c:\v_playground\lib\site-packages\flask\app.py", line 1951, in full_dispatch_request
    rv = self.handle_user_exception(e)
  File "c:\v_playground\lib\site-packages\flask\app.py", line 1815, in handle_user_exception
    return self.handle_http_exception(e)
  File "c:\v_playground\lib\site-packages\flask\app.py", line 1743, in handle_http_exception
    return handler(e)
  File "C:\GH\microblog\app\errors.py", line 7, in not_found_error
    return render_template('404.html'), 404
  File "c:\v_playground\lib\site-packages\flask\templating.py", line 140, in render_template
    ctx.app,
  File "c:\v_playground\lib\site-packages\flask\templating.py", line 120, in _render
    rv = template.render(context)
  File "c:\v_playground\lib\site-packages\jinja2\environment.py", line 1090, in render
    self.environment.handle_exception()
  File "c:\v_playground\lib\site-packages\jinja2\environment.py", line 832, in handle_exception
    reraise(*rewrite_traceback_stack(source=source))
  File "c:\v_playground\lib\site-packages\jinja2\_compat.py", line 28, in reraise
    raise value.with_traceback(tb)
  File "C:\GH\microblog\app\templates\404.html", line 1, in top-level template code
    {% extends "base.html" %}
  File "c:\v_playground\lib\site-packages\jinja2\environment.py", line 832, in handle_exception
    reraise(*rewrite_traceback_stack(source=source))
  File "c:\v_playground\lib\site-packages\jinja2\_compat.py", line 28, in reraise
    raise value.with_traceback(tb)
  File "C:\GH\microblog\app\templates\base.html", line 48, in template
    {% block app_content %}{% endblock %}
jinja2.exceptions.TemplateAssertionError: block 'app_content' defined twice
2020-02-25 14:31:10,205 INFO: Microblog startup [in C:\GH\microblog\app\__init__.py:47]
