2020-02-17 10:59:59,503 ERROR: Exception on /explore [GET] [in c:\v_playground\lib\site-packages\flask\app.py:1891]
Traceback (most recent call last):
  File "c:\v_playground\lib\site-packages\flask\app.py", line 2446, in wsgi_app
    response = self.full_dispatch_request()
  File "c:\v_playground\lib\site-packages\flask\app.py", line 1951, in full_dispatch_request
    rv = self.handle_user_exception(e)
  File "c:\v_playground\lib\site-packages\flask\app.py", line 1820, in handle_user_exception
    reraise(exc_type, exc_value, tb)
  File "c:\v_playground\lib\site-packages\flask\_compat.py", line 39, in reraise
    raise value
  File "c:\v_playground\lib\site-packages\flask\app.py", line 1949, in full_dispatch_request
    rv = self.dispatch_request()
  File "c:\v_playground\lib\site-packages\flask\app.py", line 1935, in dispatch_request
    return self.view_functions[rule.endpoint](**req.view_args)
  File "c:\v_playground\lib\site-packages\flask_login\utils.py", line 272, in decorated_view
    return func(*args, **kwargs)
  File "C:\GH\microblog\app\routes.py", line 27, in explore
    posts = Post.query.order_by(Post.timestamp()).all()
TypeError: 'InstrumentedAttribute' object is not callable
2020-02-17 11:01:55,441 INFO: Microblog startup [in C:\GH\microblog\app\__init__.py:41]
2020-02-17 11:12:50,261 INFO: Microblog startup [in C:\GH\microblog\app\__init__.py:41]
2020-02-17 11:12:55,716 ERROR: Exception on /index [GET] [in c:\v_playground\lib\site-packages\flask\app.py:1891]
Traceback (most recent call last):
  File "c:\v_playground\lib\site-packages\flask\app.py", line 2446, in wsgi_app
    response = self.full_dispatch_request()
  File "c:\v_playground\lib\site-packages\flask\app.py", line 1951, in full_dispatch_request
    rv = self.handle_user_exception(e)
  File "c:\v_playground\lib\site-packages\flask\app.py", line 1820, in handle_user_exception
    reraise(exc_type, exc_value, tb)
  File "c:\v_playground\lib\site-packages\flask\_compat.py", line 39, in reraise
    raise value
  File "c:\v_playground\lib\site-packages\flask\app.py", line 1949, in full_dispatch_request
    rv = self.dispatch_request()
  File "c:\v_playground\lib\site-packages\flask\app.py", line 1935, in dispatch_request
    return self.view_functions[rule.endpoint](**req.view_args)
  File "c:\v_playground\lib\site-packages\flask_login\utils.py", line 272, in decorated_view
    return func(*args, **kwargs)
  File "C:\GH\microblog\app\routes.py", line 22, in index
    posts = current_user.followed_posts().paginate(page, app.config['POSTS-PER-PAGE'], False)
KeyError: 'POSTS-PER-PAGE'
2020-02-17 11:12:59,850 ERROR: Exception on / [GET] [in c:\v_playground\lib\site-packages\flask\app.py:1891]
Traceback (most recent call last):
  File "c:\v_playground\lib\site-packages\flask\app.py", line 2446, in wsgi_app
    response = self.full_dispatch_request()
  File "c:\v_playground\lib\site-packages\flask\app.py", line 1951, in full_dispatch_request
    rv = self.handle_user_exception(e)
  File "c:\v_playground\lib\site-packages\flask\app.py", line 1820, in handle_user_exception
    reraise(exc_type, exc_value, tb)
  File "c:\v_playground\lib\site-packages\flask\_compat.py", line 39, in reraise
    raise value
  File "c:\v_playground\lib\site-packages\flask\app.py", line 1949, in full_dispatch_request
    rv = self.dispatch_request()
  File "c:\v_playground\lib\site-packages\flask\app.py", line 1935, in dispatch_request
    return self.view_functions[rule.endpoint](**req.view_args)
  File "c:\v_playground\lib\site-packages\flask_login\utils.py", line 272, in decorated_view
    return func(*args, **kwargs)
  File "C:\GH\microblog\app\routes.py", line 22, in index
    posts = current_user.followed_posts().paginate(page, app.config['POSTS-PER-PAGE'], False)
KeyError: 'POSTS-PER-PAGE'
2020-02-17 11:13:05,236 ERROR: Exception on / [GET] [in c:\v_playground\lib\site-packages\flask\app.py:1891]
Traceback (most recent call last):
  File "c:\v_playground\lib\site-packages\flask\app.py", line 2446, in wsgi_app
    response = self.full_dispatch_request()
  File "c:\v_playground\lib\site-packages\flask\app.py", line 1951, in full_dispatch_request
    rv = self.handle_user_exception(e)
  File "c:\v_playground\lib\site-packages\flask\app.py", line 1820, in handle_user_exception
    reraise(exc_type, exc_value, tb)
  File "c:\v_playground\lib\site-packages\flask\_compat.py", line 39, in reraise
    raise value
  File "c:\v_playground\lib\site-packages\flask\app.py", line 1949, in full_dispatch_request
    rv = self.dispatch_request()
  File "c:\v_playground\lib\site-packages\flask\app.py", line 1935, in dispatch_request
    return self.view_functions[rule.endpoint](**req.view_args)
  File "c:\v_playground\lib\site-packages\flask_login\utils.py", line 272, in decorated_view
    return func(*args, **kwargs)
  File "C:\GH\microblog\app\routes.py", line 22, in index
    posts = current_user.followed_posts().paginate(page, app.config['POSTS-PER-PAGE'], False)
KeyError: 'POSTS-PER-PAGE'
2020-02-17 11:13:56,835 INFO: Microblog startup [in C:\GH\microblog\app\__init__.py:41]
2020-02-17 11:13:59,318 ERROR: Exception on / [GET] [in c:\v_playground\lib\site-packages\flask\app.py:1891]
Traceback (most recent call last):
  File "c:\v_playground\lib\site-packages\flask\app.py", line 2446, in wsgi_app
    response = self.full_dispatch_request()
  File "c:\v_playground\lib\site-packages\flask\app.py", line 1951, in full_dispatch_request
    rv = self.handle_user_exception(e)
  File "c:\v_playground\lib\site-packages\flask\app.py", line 1820, in handle_user_exception
    reraise(exc_type, exc_value, tb)
  File "c:\v_playground\lib\site-packages\flask\_compat.py", line 39, in reraise
    raise value
  File "c:\v_playground\lib\site-packages\flask\app.py", line 1949, in full_dispatch_request
    rv = self.dispatch_request()
  File "c:\v_playground\lib\site-packages\flask\app.py", line 1935, in dispatch_request
    return self.view_functions[rule.endpoint](**req.view_args)
  File "c:\v_playground\lib\site-packages\flask_login\utils.py", line 272, in decorated_view
    return func(*args, **kwargs)
  File "C:\GH\microblog\app\routes.py", line 23, in index
    page, app.config['POSTS-PER-PAGE'], False)
KeyError: 'POSTS-PER-PAGE'
2020-02-17 11:15:15,229 INFO: Microblog startup [in C:\GH\microblog\app\__init__.py:41]
2020-02-17 11:52:28,757 INFO: Microblog startup [in C:\GH\microblog\app\__init__.py:41]
2020-02-17 12:07:49,817 INFO: Microblog startup [in C:\GH\microblog\app\__init__.py:41]
2020-02-17 12:09:16,711 ERROR: Exception on /explore [GET] [in c:\v_playground\lib\site-packages\flask\app.py:1891]
Traceback (most recent call last):
  File "c:\v_playground\lib\site-packages\flask\app.py", line 2446, in wsgi_app
    response = self.full_dispatch_request()
  File "c:\v_playground\lib\site-packages\flask\app.py", line 1951, in full_dispatch_request
    rv = self.handle_user_exception(e)
  File "c:\v_playground\lib\site-packages\flask\app.py", line 1820, in handle_user_exception
    reraise(exc_type, exc_value, tb)
  File "c:\v_playground\lib\site-packages\flask\_compat.py", line 39, in reraise
    raise value
  File "c:\v_playground\lib\site-packages\flask\app.py", line 1949, in full_dispatch_request
    rv = self.dispatch_request()
  File "c:\v_playground\lib\site-packages\flask\app.py", line 1935, in dispatch_request
    return self.view_functions[rule.endpoint](**req.view_args)
  File "c:\v_playground\lib\site-packages\flask_login\utils.py", line 272, in decorated_view
    return func(*args, **kwargs)
  File "C:\GH\microblog\app\routes.py", line 36, in explore
    return render_template('index.html', title='Explore', posts=posts.items, next_url=next_url, prev_url=prev_url)
NameError: name 'next_url' is not defined
2020-02-17 12:09:20,916 ERROR: Exception on /explore [GET] [in c:\v_playground\lib\site-packages\flask\app.py:1891]
Traceback (most recent call last):
  File "c:\v_playground\lib\site-packages\flask\app.py", line 2446, in wsgi_app
    response = self.full_dispatch_request()
  File "c:\v_playground\lib\site-packages\flask\app.py", line 1951, in full_dispatch_request
    rv = self.handle_user_exception(e)
  File "c:\v_playground\lib\site-packages\flask\app.py", line 1820, in handle_user_exception
    reraise(exc_type, exc_value, tb)
  File "c:\v_playground\lib\site-packages\flask\_compat.py", line 39, in reraise
    raise value
  File "c:\v_playground\lib\site-packages\flask\app.py", line 1949, in full_dispatch_request
    rv = self.dispatch_request()
  File "c:\v_playground\lib\site-packages\flask\app.py", line 1935, in dispatch_request
    return self.view_functions[rule.endpoint](**req.view_args)
  File "c:\v_playground\lib\site-packages\flask_login\utils.py", line 272, in decorated_view
    return func(*args, **kwargs)
  File "C:\GH\microblog\app\routes.py", line 36, in explore
    return render_template('index.html', title='Explore', posts=posts.items, next_url=next_url, prev_url=prev_url)
NameError: name 'next_url' is not defined
