2020-02-27 13:24:47,551 INFO: Microblog startup [in C:\GH\microblog\app\__init__.py:52]
2020-02-27 13:24:59,219 INFO: Microblog startup [in C:\GH\microblog\app\__init__.py:52]
2020-02-27 13:25:03,985 ERROR: Exception on /index [GET] [in c:\gh\microblog\venv\lib\site-packages\flask\app.py:1891]
Traceback (most recent call last):
  File "c:\gh\microblog\venv\lib\site-packages\sqlalchemy\engine\base.py", line 1246, in _execute_context
    cursor, statement, parameters, context
  File "c:\gh\microblog\venv\lib\site-packages\sqlalchemy\engine\default.py", line 588, in do_execute
    cursor.execute(statement, parameters)
sqlite3.OperationalError: no such table: followers

The above exception was the direct cause of the following exception:

Traceback (most recent call last):
  File "c:\gh\microblog\venv\lib\site-packages\flask\app.py", line 2446, in wsgi_app
    response = self.full_dispatch_request()
  File "c:\gh\microblog\venv\lib\site-packages\flask\app.py", line 1951, in full_dispatch_request
    rv = self.handle_user_exception(e)
  File "c:\gh\microblog\venv\lib\site-packages\flask\app.py", line 1820, in handle_user_exception
    reraise(exc_type, exc_value, tb)
  File "c:\gh\microblog\venv\lib\site-packages\flask\_compat.py", line 39, in reraise
    raise value
  File "c:\gh\microblog\venv\lib\site-packages\flask\app.py", line 1949, in full_dispatch_request
    rv = self.dispatch_request()
  File "c:\gh\microblog\venv\lib\site-packages\flask\app.py", line 1935, in dispatch_request
    return self.view_functions[rule.endpoint](**req.view_args)
  File "c:\gh\microblog\venv\lib\site-packages\flask_login\utils.py", line 261, in decorated_view
    return func(*args, **kwargs)
  File "C:\GH\microblog\app\routes.py", line 34, in index
    page, app.config['POSTS_PER_PAGE'], False)
  File "c:\gh\microblog\venv\lib\site-packages\flask_sqlalchemy\__init__.py", line 496, in paginate
    items = self.limit(per_page).offset((page - 1) * per_page).all()
  File "c:\gh\microblog\venv\lib\site-packages\sqlalchemy\orm\query.py", line 3233, in all
    return list(self)
  File "c:\gh\microblog\venv\lib\site-packages\sqlalchemy\orm\query.py", line 3389, in __iter__
    return self._execute_and_instances(context)
  File "c:\gh\microblog\venv\lib\site-packages\sqlalchemy\orm\query.py", line 3414, in _execute_and_instances
    result = conn.execute(querycontext.statement, self._params)
  File "c:\gh\microblog\venv\lib\site-packages\sqlalchemy\engine\base.py", line 982, in execute
    return meth(self, multiparams, params)
  File "c:\gh\microblog\venv\lib\site-packages\sqlalchemy\sql\elements.py", line 293, in _execute_on_connection
    return connection._execute_clauseelement(self, multiparams, params)
  File "c:\gh\microblog\venv\lib\site-packages\sqlalchemy\engine\base.py", line 1101, in _execute_clauseelement
    distilled_params,
  File "c:\gh\microblog\venv\lib\site-packages\sqlalchemy\engine\base.py", line 1250, in _execute_context
    e, statement, parameters, cursor, context
  File "c:\gh\microblog\venv\lib\site-packages\sqlalchemy\engine\base.py", line 1476, in _handle_dbapi_exception
    util.raise_from_cause(sqlalchemy_exception, exc_info)
  File "c:\gh\microblog\venv\lib\site-packages\sqlalchemy\util\compat.py", line 398, in raise_from_cause
    reraise(type(exception), exception, tb=exc_tb, cause=cause)
  File "c:\gh\microblog\venv\lib\site-packages\sqlalchemy\util\compat.py", line 152, in reraise
    raise value.with_traceback(tb)
  File "c:\gh\microblog\venv\lib\site-packages\sqlalchemy\engine\base.py", line 1246, in _execute_context
    cursor, statement, parameters, context
  File "c:\gh\microblog\venv\lib\site-packages\sqlalchemy\engine\default.py", line 588, in do_execute
    cursor.execute(statement, parameters)
sqlalchemy.exc.OperationalError: (sqlite3.OperationalError) no such table: followers
[SQL: SELECT anon_1.post_id AS anon_1_post_id, anon_1.post_body AS anon_1_post_body, anon_1.post_timestamp AS anon_1_post_timestamp, anon_1.post_user_id AS anon_1_post_user_id, anon_1.post_language AS anon_1_post_language 
FROM (SELECT post.id AS post_id, post.body AS post_body, post.timestamp AS post_timestamp, post.user_id AS post_user_id, post.language AS post_language 
FROM post JOIN followers ON followers.followed_id = post.user_id 
WHERE followers.follower_id = ? UNION SELECT post.id AS post_id, post.body AS post_body, post.timestamp AS post_timestamp, post.user_id AS post_user_id, post.language AS post_language 
FROM post 
WHERE post.user_id = ?) AS anon_1 ORDER BY anon_1.post_timestamp DESC
 LIMIT ? OFFSET ?]
[parameters: (2, 2, 25, 0)]
(Background on this error at: http://sqlalche.me/e/e3q8)
2020-02-27 13:25:52,174 INFO: Microblog startup [in C:\GH\microblog\app\__init__.py:52]
2020-02-27 13:27:03,762 INFO: Microblog startup [in C:\GH\microblog\app\__init__.py:52]
2020-02-27 13:27:29,624 INFO: Microblog startup [in C:\GH\microblog\app\__init__.py:52]
2020-02-27 13:27:38,964 INFO: Microblog startup [in C:\GH\microblog\app\__init__.py:52]
2020-02-27 13:27:53,680 INFO: Microblog startup [in C:\GH\microblog\app\__init__.py:52]
2020-02-27 13:28:28,516 INFO: Microblog startup [in C:\GH\microblog\app\__init__.py:52]
2020-04-15 14:42:28,449 INFO: Microblog startup [in C:\GH\microblog\app\__init__.py:52]
